Workbook

Sheet Read me
A1: Item | B1: Description
A2: Colorado historical hazardous industrial sites, 1961–2002
A3: Method | B3: Frickel & Elliott (Sites Unseen, 2018) relic-site approach applied to the Colorado Directory of Manufacturers, 13 editions 1961–2002.
A4: Hazardous sectors (F&E) | B4: SIC 28 chemicals, 29 petroleum refining, 30 rubber & plastics, 33 primary metals, 34 fabricated metals, 35 industrial machinery, 37 transportation equipment (NAICS 325, 324, 326, 331, 332, 333, 336 for 1999–2002).
A5: Extended sectors | B5: Not in F&E but commonly contaminating: wood preserving 2491, leather tanning 3111, electronic components & circuit boards 3671–3679, batteries 3691–3692, photographic chemicals 3861, metal mining / ore milling 10xx.
A6: Site | B6: All directory listings geocoded to street level within 30 m of each other, across all years.
A7: radar | B7: Best match to a current inventory: Cleanup / contamination list (EPA SEMS/Superfund, ACRES brownfields, FRS state/federal cleanup programs; CDPHE VCUP, brownfields, Superfund, RCRA corrective action, institutional controls, UMTRA, federal facilities) — matched if within 75 m, inside the site boundary, or same name within 250 m or same address. TRI reporter (100 m or name/address). RCRA hazardous-waste handler (40 m or name/address). Other EPA permit only (40 m or name/address). Not on any list = no match in any of these.
A8: confidence | B8: high = street-level geocode AND industry code printed in the directory; medium = one of the two; low = neither (inferred industry and approximate location).
A9: geo_level | B9: address = number interpolated on the matching TIGER/Line 2023 street segment; address_approx = OCR-tolerant street match, neighbouring ZIP, or nearest segment end (verify before field work).
A10: Sources | B10: Colorado Directory of Manufacturers (scans supplied by user); US EPA Facility Registry Service state file for Colorado (downloaded 16 Oct 2026); EPA TRI facility table (Envirofacts, 16 Oct 2026); CDPHE HMWMD layers, geodata.colorado.gov (16 Oct 2026); US Census TIGER/Line 2023 ADDRFEAT.
A11: Limits | B11: OCR errors in names, numbers and ZIPs; 1961–1965 editions have no ZIP codes; 2002 covers only the second half of the alphabet of places (part 1 missing); 1971 and 1985 volumes appear partial; renumbered historical streets fall back to ZIP centroids (listed separately). A site absent from regulatory lists is a candidate for review, not evidence of contamination.

Sheet Summary
A1: radar | B1: F&E sites | C1: share | D1: high confidence | E1: medium | F1: low
A2: Cleanup / contamination list | B2: =COUNTIF('All F&E hazardous sites'!$B$2:$B$3170,A2) | C2: =IFERROR(B2/$B$8,0) | D2: =COUNTIFS('All F&E hazardous sites'!$B$2:$B$3170,$A2,'All F&E hazardous sites'!$C$2:$C$3170,"high") | E2: =COUNTIFS('All F&E hazardous sites'!$B$2:$B$3170,$A2,'All F&E hazardous sites'!$C$2:$C$3170,"medium") | F2: =COUNTIFS('All F&E hazardous sites'!$B$2:$B$3170,$A2,'All F&E hazardous sites'!$C$2:$C$3170,"low")
A3: TRI reporter | B3: =COUNTIF('All F&E hazardous sites'!$B$2:$B$3170,A3) | C3: =IFERROR(B3/$B$8,0) | D3: =COUNTIFS('All F&E hazardous sites'!$B$2:$B$3170,$A3,'All F&E hazardous sites'!$C$2:$C$3170,"high") | E3: =COUNTIFS('All F&E hazardous sites'!$B$2:$B$3170,$A3,'All F&E hazardous sites'!$C$2:$C$3170,"medium") | F3: =COUNTIFS('All F&E hazardous sites'!$B$2:$B$3170,$A3,'All F&E hazardous sites'!$C$2:$C$3170,"low")
A4: RCRA hazardous-waste handler | B4: =COUNTIF('All F&E hazardous sites'!$B$2:$B$3170,A4) | C4: =IFERROR(B4/$B$8,0) | D4: =COUNTIFS('All F&E hazardous sites'!$B$2:$B$3170,$A4,'All F&E hazardous sites'!$C$2:$C$3170,"high") | E4: =COUNTIFS('All F&E hazardous sites'!$B$2:$B$3170,$A4,'All F&E hazardous sites'!$C$2:$C$3170,"medium") | F4: =COUNTIFS('All F&E hazardous sites'!$B$2:$B$3170,$A4,'All F&E hazardous sites'!$C$2:$C$3170,"low")
A5: Solid waste facility | B5: =COUNTIF('All F&E hazardous sites'!$B$2:$B$3170,A5) | C5: =IFERROR(B5/$B$8,0) | D5: =COUNTIFS('All F&E hazardous sites'!$B$2:$B$3170,$A5,'All F&E hazardous sites'!$C$2:$C$3170,"high") | E5: =COUNTIFS('All F&E hazardous sites'!$B$2:$B$3170,$A5,'All F&E hazardous sites'!$C$2:$C$3170,"medium") | F5: =COUNTIFS('All F&E hazardous sites'!$B$2:$B$3170,$A5,'All F&E hazardous sites'!$C$2:$C$3170,"low")
A6: Other EPA permit only | B6: =COUNTIF('All F&E hazardous sites'!$B$2:$B$3170,A6) | C6: =IFERROR(B6/$B$8,0) | D6: =COUNTIFS('All F&E hazardous sites'!$B$2:$B$3170,$A6,'All F&E hazardous sites'!$C$2:$C$3170,"high") | E6: =COUNTIFS('All F&E hazardous sites'!$B$2:$B$3170,$A6,'All F&E hazardous sites'!$C$2:$C$3170,"medium") | F6: =COUNTIFS('All F&E hazardous sites'!$B$2:$B$3170,$A6,'All F&E hazardous sites'!$C$2:$C$3170,"low")
A7: Not on any list | B7: =COUNTIF('All F&E hazardous sites'!$B$2:$B$3170,A7) | C7: =IFERROR(B7/$B$8,0) | D7: =COUNTIFS('All F&E hazardous sites'!$B$2:$B$3170,$A7,'All F&E hazardous sites'!$C$2:$C$3170,"high") | E7: =COUNTIFS('All F&E hazardous sites'!$B$2:$B$3170,$A7,'All F&E hazardous sites'!$C$2:$C$3170,"medium") | F7: =COUNTIFS('All F&E hazardous sites'!$B$2:$B$3170,$A7,'All F&E hazardous sites'!$C$2:$C$3170,"low")
A8: Total | B8: =SUM(B2:B7) | C8: =IFERROR(B8/$B$8,0) | D8: =SUM(D2:D7) | E8: =SUM(E2:E7) | F8: =SUM(F2:F7)
A10: Counts recalculate from the All F&E hazardous sites sheet.

Sheet Hidden sites
A1: site_id | B1: radar | C1: confidence | D1: address | E1: city | F1: county | G1: zip | H1: lat | I1: lon | J1: geo_level | K1: fe_sectors | L1: ext_sectors | M1: first_year | N1: last_year | O1: hazard_years | P1: n_editions | Q1: n_establishments | R1: n_hazard_establishments | S1: earliest_est | T1: hazard_firms | U1: all_firms | V1: industry_evidence | W1: cleanup_match | X1: tri_match | Y1: rcra_handler_match | Z1: solid_waste_match | AA1: other_epa_match | AB1: cleanup_nearest | AC1: cleanup_nearest_m | AD1: tri_nearest | AE1: tri_nearest_m | AF1: rcra_handler_nearest | AG1: rcra_handler_nearest_m
A2: S01322 | B2: Not on any list | C2: high | D2: 4950 E 71ST | E2: COMMERCE CITY | F2: Adams | G2: 80022 | H2: 39.824981 | I2: -104.92769 | J2: address | K2: Fabricated metals | M2: 1967 | N2: 1974 | O2: 1967;1973;1974 | P2: 3 | Q2: 2 | R2: 2 | T2: FISCUS FEED MILL EQUIPMENT (1967; SIC 3441) | FISCUS STEEL FABRICATION (1973-1974; SIC 3441) | U2: FISCUS FEED MILL EQUIPMENT (1967) | FISCUS STEEL FABRICATION (1973) | V2: printed | AB2: OIL & SOLVENT PROCESS COMPANY (OSCO) | AC2: 102 | AF2: DREITH AUTO BODY | AG2: 58
A3: S01324 | B3: Not on any list | C3: high | D3: 6931 LOWELL BLVD | E3: DENVER | F3: Adams | G3: 80221 | H3: 39.822349 | I3: -105.03447 | J3: address | K3: Fabricated metals; Industrial machinery; Rubber & plastics | M3: 1967 | N3: 1988 | O3: 1973;1980;1983;1988 | P3: 5 | Q3: 4 | R3: 3 | S3: 1966 | T3: WOOD LAND PLASTICS, INC (1973; SIC 3079,3544) | REICHERT SCREW MACHINE (1980-1988; SIC 3535,3452,3423) | VELMAR ENGRAVING CO. (1980; SIC 3479,3079,3953) | U3: (1967) | WOOD LAND PLASTICS, INC (1973) | REICHERT SCREW MACHINE (1980) | VELMAR ENGRAVING CO. (1980) | V3: printed | AB3: Heffley and Guildner Properties | AC3: 219 | AF3: CAMP STONE COMPANY, INC. | AG3: 94
A4: S01331 | B4: Not on any list | C4: high | D4: 7711 SHOSHONE | E4: DENVER | F4: Adams | G4: 80221 | H4: 39.836558 | I4: -105.00978 | J4: address | K4: Chemicals | M4: 1967 | N4: 1974 | O4: 1968;1970;1974 | P4: 4 | Q4: 3 | R4: 2 | S4: 1965 | T4: TRUMCC MFG CCRP (1968; SIC 2841,2842) | TRUMCO MFG CORP (1970-1974; SIC 2841,2842) | U4: 5199 LEATHER GOCOS NE C TRUMCO MFG CORP ALAMOSA (1967) | TRUMCC MFG CCRP (1968) | TRUMCO MFG CORP (1970) | V4: printed
A5: S01336 | B5: Not on any list | C5: high | D5: 16200 E COLFAX | E5: AURORA | F5: Adams | G5: 80011 | H5: 39.740102 | I5: -104.79951 | J5: address | K5: Fabricated metals; Petroleum refining | L5: Asphalt paving mixtures | M5: 1967 | N5: 1973 | O5: 1967;1973 | P5: 2 | Q5: 2 | R5: 2 | S5: 1961 | T5: AURORA ASPHALT + PAVING CO (1967; SIC 2951,3444) | AURORA ASPHALT # PAVING CO INC (1973; SIC 2951) | U5: AURORA ASPHALT + PAVING CO (1967) | AURORA ASPHALT # PAVING CO INC (1973) | V5: printed | AF5: AUTOZONE #802 | AG5: 76
A6: S01406 | B6: Not on any list | C6: high | D6: 3600 PECOS | E6: DENVER | F6: Adams | G6: 80221 | H6: 39.766935 | I6: -105.00645 | J6: address | K6: Fabricated metals; Primary metals; Transportation equipment | M6: 1967 | N6: 1968 | O6: 1967;1968 | P6: 2 | Q6: 2 | R6: 2 | S6: 1956 | T6: ALADDIN IRON + STEEL CORP (1967; SIC 3441,3352) | GENERATCR EXCHANGE CC INC (1968; SIC 3714) | U6: ALADDIN IRON + STEEL CORP (1967) | GENERATCR EXCHANGE CC INC (1968) | V6: printed
A7: S02176 | B7: Not on any list | C7: high | D7: 8777 BRIGHTON RD | E7: COMMERCE CITY | F7: Adams | G7: 80022 | H7: 39.855611 | I7: -104.91362 | J7: address | K7: Industrial machinery; Rubber & plastics; Transportation equipment | M7: 1973 | N7: 1983 | O7: 1973;1974;1977;1980 | P7: 5 | Q7: 2 | R7: 2 | S7: 1954 | T7: EMPIRE CORPORATION (1973-1980; SIC 2394,3079,3523) | EMPIRE CORPIRATION (1977; SIC 3161,3523,2394) | U7: EMPIRE CORPORATION (1973) | EMPIRE CORPIRATION (1977) | V7: printed | AF7: GRAGAR INC | AG7: 151
A8: S02189 | B8: Not on any list | C8: high | D8: 345 S MAIN ST | E8: BRIGHTON | F8: Adams | G8: 80601 | H8: 39.981589 | I8: -104.8224 | J8: address | K8: Industrial machinery | M8: 1973 | N8: 1973 | O8: 1973 | P8: 1 | Q8: 1 | R8: 1 | T8: GUNNISON CATTLE CHUTE MFG INC (1973; SIC 3523) | U8: GUNNISON CATTLE CHUTE MFG INC (1973) | V8: printed
A9: S02194 | B9: Not on any list | C9: high | D9: 4905 OLIVE | E9: COMMERCE CITY | F9: Adams | G9: 80022 | H9: 39.785339 | I9: -104.90692 | J9: address | K9: Industrial machinery; Transportation equipment | M9: 1973 | N9: 1974 | O9: 1973;1974 | P9: 2 | Q9: 1 | R9: 1 | S9: 1968 | T9: ASSOCIATED ENGINEERING + MFG (1973-1974; SIC 2452,2439,3751) | U9: ASSOCIATED ENGINEERING + MFG (1973) | V9: printed | AF9: BOB SMITH OILS INC | AG9: 59
A10: S02199 | B10: Not on any list | C10: high | D10: 2000 W 60TH AVE | E10: DENVER | F10: Adams | G10: 80221 | H10: 39.805578 | I10: -105.01484 | J10: address | K10: Rubber & plastics | M10: 1973 | N10: 1983 | O10: 1973;1974;1983 | P10: 3 | Q10: 2 | R10: 2 | S10: 1970 | T10: DREW FOAM OF COLO INC (1973-1974; SIC 3079) | DREW FOAM OF COLO INC (1983; SIC 3079) | U10: DREW FOAM OF COLO INC (1973) | DREW FOAM OF COLO INC (1983) | V10: printed | AB10: 60TH AND ALCOTT | AC10: 225 | AF10: CENTRAL READY MIX, LLC | AG10: 212
A11: S02201 | B11: Not on any list | C11: high | D11: 6425 BRIGHTON BLVD | E11: COMMERCE CITY | F11: Adams | G11: 80022 | H11: 39.81317 | I11: -104.93678 | J11: address | K11: Fabricated metals; Industrial machinery | M11: 1973 | N11: 1990 | O11: 1973;1974;1980;1988;1990 | P11: 5 | Q11: 1 | R11: 1 | S11: 1927 | T11: EASON SERVICE SYSTEM INC (1973-1990; SIC 3469,3591,3599) | U11: EASON SERVICE SYSTEM INC (1973) | V11: printed | AF11: GAHAGEN IRON&METAL | AG11: 46
A12: S02208 | B12: Not on any list | C12: high | D12: 4875 NEWPORT | E12: COMMERCE CITY | F12: Adams | G12: 80022 | H12: 39.784894 | I12: -104.91009 | J12: address | K12: Fabricated metals | M12: 1973 | N12: 1974 | O12: 1973;1974 | P12: 2 | Q12: 1 | R12: 1 | S12: 1969 | T12: MAC STEEL, INC (1973-1974; SIC 3448,3441) | U12: MAC STEEL, INC (1973) | V12: printed | AB12: CDM MACHINING AND FABRICATION | AC12: 180 | AD12: MESA FIBERGLASS INC | AE12: 211 | AF12: MARKETING DATA SOLUTIONS, LLC DBA REGION 8 INTERNATIONAL | AG12: 78
A13: S02210 | B13: Not on any list | C13: high | D13: 5750 FAIRFAX | E13: COMMERCE CITY | F13: Adams | G13: 80022 | H13: 39.800988 | I13: -104.9284 | J13: address | K13: Industrial machinery | M13: 1973 | N13: 1974 | O13: 1973;1974 | P13: 2 | Q13: 1 | R13: 1 | S13: 1970 | T13: MULTI-POINT TOOL CORP (1973-1974; SIC 3545) | U13: MULTI-POINT TOOL CORP (1973) | V13: printed | AB13: TIRE DISTRIBUTION SYSTEMS, INC. | AC13: 209 | AF13: STEWART & STEVENSON POWER INC | AG13: 96
A14: S02230 | B14: Not on any list | C14: high | D14: 1225 E 70TH | E14: THORNTON | F14: Adams | G14: 80229 | H14: 39.82527 | I14: -104.97114 | J14: address | K14: Industrial machinery; Transportation equipment | M14: 1973 | N14: 1973 | O14: 1973 | P14: 1 | Q14: 1 | R14: 1 | S14: 1970 | T14: THORTON MACHINE + TOOL CO (1973; SIC 3519,3714) | U14: THORTON MACHINE + TOOL CO (1973) | V14: printed | AB14: TruStile Properties LLC II | AC14: 214 | AD14: TRUSTILE DOORS, LLC | AE14: 232 | AF14: CHASIN DREAMS | AG14: 171
A15: S02237 | B15: Not on any list | C15: high | D15: 11494 EMERSON | E15: NORTHGLENN | F15: Adams | G15: 80233 | H15: 39.904742 | I15: -104.97494 | J15: address | K15: Rubber & plastics | M15: 1973 | N15: 1974 | O15: 1973;1974 | P15: 2 | Q15: 1 | R15: 1 | S15: 1972 | T15: S + S ENTERPRISES (1973-1974; SIC 3079,3299) | U15: S + S ENTERPRISES (1973) | V15: printed | AF15: MALLEY DRIVE ELEMENTARY SCHOOL | AG15: 245
A16: S02240 | B16: Not on any list | C16: high | D16: 7530 STUART ST | E16: WESTMINSTER | F16: Adams | G16: 80030 | H16: 39.833366 | I16: -105.04522 | J16: address | K16: Rubber & plastics | M16: 1973 | N16: 1973 | O16: 1973 | P16: 1 | Q16: 1 | R16: 1 | S16: 1971 | T16: MULTIFOAM CO INC (1973; SIC 3079) | U16: MULTIFOAM CO INC (1973) | V16: printed | AB16: POUSKY | AC16: 183
A17: S02241 | B17: Not on any list | C17: high | D17: 8320 TURNPIKE OR | E17: WESTMINSTER | F17: Adams | G17: 80030 | H17: 39.848097 | I17: -105.04677 | J17: address | K17: Industrial machinery | M17: 1973 | N17: 1973 | O17: 1973 | P17: 1 | Q17: 1 | R17: 1 | S17: 1971 | T17: NATL WASTE TREATMENT CO INC (1973; SIC 3589) | U17: NATL WASTE TREATMENT CO INC (1973) | V17: printed
A18: S02471 | B18: Not on any list | C18: high | D18: 431 W 8TH AVE | E18: DENVER | F18: Adams | G18: 80221 | H18: 39.728932 | I18: -104.9935 | J18: address | K18: Fabricated metals | M18: 1973 | N18: 1973 | O18: 1973 | P18: 1 | Q18: 1 | R18: 1 | S18: 1958 | T18: KNERL SHEET METAL INC (1973; SIC 3444) | U18: KNERL SHEET METAL INC (1973) | V18: printed | AF18: CO COLLISION CENTER DBA PERRY + TERRY C | AG18: 218
A19: S02748 | B19: Not on any list | C19: high | D19: 7135 NEWTON | E19: WESTMINSTER | F19: Adams | G19: 80030 | H19: 39.825705 | I19: -105.03698 | J19: address | K19: Fabricated metals; Industrial machinery; Primary metals; Rubber & plastics; Transportation equipment | M19: 1974 | N19: 1992 | O19: 1974;1980;1983;1988;1990;1992 | P19: 6 | Q19: 11 | R19: 10 | S19: 1963 | T19: HURTT MACHINE AND TOOL (1974-1990; SIC 3591) | MOLD SPECIALTY CO (1974-1990; SIC 3324) | A-1 METAL PRODUCTS (1980-1983; SIC 3446) | GUAR OWN MFG MACHINE SHOP (1980; SIC 3714,3499,3599) | PLASTIC PARTS OUPLICATORS (1980; SIC 3544) | BEL-PRO PRODUCTS (1983; SIC 3699,3551,3599) | PARTS DUPLICATORS (1983; SIC 3544) | SKYLINE MANUFACTURING INC (1983-1990; SIC 3544,3599) | JOSEPH M FORTUNATO (1988-1990; SIC 3599) | ‘CLEVECO PLASIICS (1992; SIC 3089) | U19: BELLVIEW WOOD PRODUCTS (1974) | HURTT MACHINE AND TOOL (1974) | MOLD SPECIALTY CO (1974) | A-1 METAL PRODUCTS (1980) | GUAR OWN MFG MACHINE SHOP (1980) | PLASTIC PARTS OUPLICATORS (1980) | BEL-PRO PRODUCTS (1983) | PARTS DUPLICATORS (1983) | SKYLINE MANUFACTURING INC (1983) | JOSEPH M FORTUNATO (1988) | ‘CLEVECO PLASIICS (1992) | V19: printed | AB19: WESTMINSTER TOD | AC19: 227 | AF19: CLEASBY MFG OF DENVER | AG19: 56
A20: S02750 | B20: Not on any list | C20: high | D20: 15592 E BATAVIA DR | E20: AURORA | F20: Adams | G20: 80011 | H20: 39.742523 | I20: -104.80669 | J20: address | K20: Fabricated metals; Industrial machinery; Transportation equipment | L20: Electronic components | M20: 1974 | N20: 1992 | O20: 1974;1977;1980;1983;1990;1992 | P20: 6 | Q20: 9 | R20: 5 | S20: 1969 | T20: DENVER RECORDING CO INC (1974; SIC 3679) | DOUBLE v ENGINEERING INC (1974; SIC 3799,3751) | RAY SMITH AIR FILTER CO (1977-1980; SIC 3599) | TIGER MFC CO INC (1983; SIC 3432,3494) | FOGG SYSTEM CO INC. (1990-1992; SIC 3679) | U20: DENVER RECORDING CO INC (1974) | DOUBLE v ENGINEERING INC (1974) | FOGG SYSTEM COMPANY INC (1977) | RAY SMITH AIR FILTER CO (1977) | FOGG SYSTEM COMPANY ING (1980) | COVAULT PRINTING CO (1983) | TIGER MFC CO INC (1983) | COLORADO COMPUTER BROKERS INC (1992) | MCMULLEN SIGN & BANNER: (1992) | V20: printed | AB20: Fitzsimons Promenade | AC20: 153 | AF20: M&M AUTO RECONDITIONING INC | AG20: 81
A21: S02776 | B21: Not on any list | C21: high | D21: 1001 DAKIN | E21: DENVER | F21: Adams | G21: 80221 | H21: 39.834181 | I21: -104.99897 | J21: address | K21: Fabricated metals | M21: 1974 | N21: 1974 | O21: 1974 | P21: 1 | Q21: 1 | R21: 1 | S21: 1969 | T21: NOVA ENGRAVING CO (1974; SIC 3479) | U21: NOVA ENGRAVING CO (1974) | V21: printed
A22: S02781 | B22: Not on any list | C22: high | D22: 9966 LOGAN | E22: THORNTON | F22: Adams | G22: 80229 | H22: 39.877096 | I22: -104.9821 | J22: address | K22: Chemicals | M22: 1974 | N22: 1977 | O22: 1974 | P22: 2 | Q22: 2 | R22: 1 | S22: 1973 | T22: CONTROL PROCUCTS INC (1974; SIC 2831) | U22: CONTROL PROCUCTS INC (1974) | ALAMOSA (1977) | V22: printed | AF22: GANDER MOUNTAIN #421 | AG22: 153
A23: S02929 | B23: Not on any list | C23: high | D23: 981 E 64TH AVE | E23: THORNTON | F23: Adams | G23: 80229 | H23: 39.812732 | I23: -104.97534 | J23: address | K23: Fabricated metals; Transportation equipment | M23: 1974 | N23: 1980 | O23: 1974;1980 | P23: 2 | Q23: 2 | R23: 2 | S23: 1953 | T23: LIFETIME FEACE CO (1974; SIC 2499,3496) | MITCHELL AND SONS INC (1980; SIC 3792,2452) | U23: LIFETIME FEACE CO (1974) | MITCHELL AND SONS INC (1980) | V23: printed | AD23: CARDINAL INDL FINISHES INC | AE23: 136 | AF23: DIAGNOSTIC IMAGING INCORPORATED | AG23: 49
A24: S03181 | B24: Not on any list | C24: high | D24: 21 N 1ST AVE | E24: BRIGHTON | F24: Adams | G24: 80601 | H24: 39.987074 | I24: -104.82238 | J24: address | K24: Industrial machinery | M24: 1977 | N24: 1977 | O24: 1977 | P24: 1 | Q24: 1 | R24: 1 | S24: 1961 | T24: BRIGHTON SENTINEL (1977; SIC 2711,3523) | U24: BRIGHTON SENTINEL (1977) | V24: printed | AF24: CARQUEST AUTO PARTS | AG24: 145
A25: S03190 | B25: Not on any list | C25: high | D25: 4540 E 60 AVE | E25: COMMERCE CITY | F25: Adams | G25: 80022 | H25: 39.805512 | I25: -104.93367 | J25: address | K25: Fabricated metals; Industrial machinery; Primary metals | M25: 1977 | N25: 1990 | O25: 1977;1983;1988;1990 | P25: 4 | Q25: 4 | R25: 4 | S25: 1966 | T25: SCHMIDT ENVIRONMENTAL ARODUCTS (1977; SIC 3433,3589) | SCHMIDT INCINERATOR CO (1977; SIC 3441) | ANDERSON INDUSTRIES» INC (1983-1990; SIC 3272,3446,3441) | CHRISTMAS CARDS ANDERSON INDUSTRIES (1988; SIC 3441) | U25: SCHMIDT ENVIRONMENTAL ARODUCTS (1977) | SCHMIDT INCINERATOR CO (1977) | ANDERSON INDUSTRIES» INC (1983) | CHRISTMAS CARDS ANDERSON INDUSTRIES (1988) | V25: printed | AB25: DEXTER & 60TH | AC25: 152 | AF25: 4545 E 60TH AVE COMMERCE CITY CO | AG25: 51
A26: S03572 | B26: Not on any list | C26: high | D26: 12801 BRIGHTON RD | E26: BRIGHTON | F26: Adams | G26: 80601 | H26: 39.927205 | I26: -104.86081 | J26: address | K26: Industrial machinery | M26: 1980 | N26: 1990 | O26: 1980;1988;1990 | P26: 3 | Q26: 1 | R26: 1 | S26: 1955 | T26: BROMLEY MACHINE COMPANY (1980-1990; SIC 3591) | U26: BROMLEY MACHINE COMPANY (1980) | V26: printed
A27: S03595 | B27: Not on any list | C27: high | D27: 2890 W 62ND AYE | E27: DENVER | F27: Adams | G27: 80221 | H27: 39.809226 | I27: -105.02267 | J27: address | K27: Fabricated metals | M27: 1980 | N27: 1992 | O27: 1980;1988;1992 | P27: 3 | Q27: 2 | R27: 2 | S27: 1976 | T27: ARROW SHEET METAL PRODUCTS CO (1980-1992; SIC 3444) | BREBU CHESS METAL (1988; SIC 3444) | U27: ARROW SHEET METAL PRODUCTS CO (1980) | BREBU CHESS METAL (1988) | V27: printed | AF27: PIONEER MOBILE HOME PARK | AG27: 182
A28: S03623 | B28: Not on any list | C28: high | D28: 12850 E 112TH AVE | E28: HENDERSON | F28: Adams | G28: 80640 | H28: 39.899734 | I28: -104.83081 | J28: address | K28: Industrial machinery | M28: 1980 | N28: 1980 | O28: 1980 | P28: 1 | Q28: 1 | R28: 1 | S28: 1978 | T28: CONDOR ENGINEERING * MANUFACTURING INC (1980; SIC 3533) | U28: CONDOR ENGINEERING * MANUFACTURING INC (1980) | V28: printed
A29: S04175 | B29: Not on any list | C29: high | D29: 6051 W 95TH AVE | E29: WESTMINSTER | F29: Adams | G29: 80030 | H29: 39.868987 | I29: -105.06304 | J29: address | K29: Industrial machinery | M29: 1980 | N29: 1988 | O29: 1980 | P29: 3 | Q29: 3 | R29: 1 | S29: 1967 | T29: R E B PRODUCTS INC (1980; SIC 3599) | U29: R E B PRODUCTS INC (1980) | TREND HOMES (1983) | TREND HOMES SEPPERSON (1988) | V29: printed
A30: S04434 | B30: Not on any list | C30: high | D30: 14303 E MONCRIEFF | E30: AURORA | F30: Adams | G30: 80011 | H30: 39.764539 | I30: -104.82035 | J30: address | K30: Fabricated metals | M30: 1983 | N30: 1983 | O30: 1983 | P30: 1 | Q30: 1 | R30: 1 | S30: 1976 | T30: KRESTMARK INDUSTRIES OF COLORADG (1983; SIC 3442) | U30: KRESTMARK INDUSTRIES OF COLORADG (1983) | V30: printed | AF30: BEMIS PACKAGING MACHINERY CO | AG30: 45
A31: S04437 | B31: Not on any list | C31: high | D31: 1790 JASPER ST | E31: AURORA | F31: Adams | G31: 80011 | H31: 39.745131 | I31: -104.80586 | J31: address | K31: Chemicals; Industrial machinery | M31: 1983 | N31: 1990 | O31: 1983;1988;1990 | P31: 3 | Q31: 3 | R31: 2 | S31: 1973 | T31: RAY SMITH AIR FILTER INC (1983-1988; SIC 3564) | RAY SMITH AIR FILTER INC (1990; SIC 3564) | U31: RAY SMITH AIR FILTER INC (1983) | BROCK SIGNS (1990) | RAY SMITH AIR FILTER INC (1990) | V31: printed | AF31: ENVIRO HEALTH RESEARCH & TSTN | AG31: 109
A32: S04447 | B32: Not on any list | C32: high | D32: 4950 OLIVE ST | E32: COMMERCE CITY | F32: Adams | G32: 80022 | H32: 39.786376 | I32: -104.90693 | J32: address | K32: Industrial machinery | M32: 1983 | N32: 1983 | O32: 1983 | P32: 1 | Q32: 1 | R32: 1 | S32: 1982 | T32: GAS ENGINEERING SERVICES INC (1983; SIC 3563,3561,3621) | U32: GAS ENGINEERING SERVICES INC (1983) | V32: printed | AF32: SINGLE SOURCE INC | AG32: 100
A33: S04476 | B33: Not on any list | C33: high | D33: 9800 E 96TH AVE | E33: HENDERSON | F33: Adams | G33: 80640 | H33: 39.870743 | I33: -104.87365 | J33: address | K33: Petroleum refining | L33: Asphalt paving mixtures | M33: 1983 | N33: 1988 | O33: 1983;1988 | P33: 2 | Q33: 2 | R33: 2 | S33: 1980 | T33: DAKOLIGS CONSTRUCTION CO INC D/B/A/ (1983; SIC 2951) | AGGREGATE+CONCRETE D.B.A.-DAKOLIOS ASPHALT PAVING (1988; SIC 2951,3295) | U33: DAKOLIGS CONSTRUCTION CO INC D/B/A/ (1983) | AGGREGATE+CONCRETE D.B.A.-DAKOLIOS ASPHALT PAVING (1988) | V33: printed | AF33: COLORADO ANALYTICAL LABORATORIES INC | AG33: 207
A34: S04477 | B34: Not on any list | C34: high | D34: 12202 BRIGHTON RD | E34: HENDERSON | F34: Adams | G34: 80640 | H34: 39.917968 | I34: -104.86783 | J34: address | K34: Fabricated metals; Transportation equipment | M34: 1983 | N34: 1990 | O34: 1983;1988;1990 | P34: 3 | Q34: 3 | R34: 3 | S34: 1965 | T34: HENDERSON MANUFACTURING CO (1983-1990; SIC 3444,3431) | BARRELS KOOLON CORP (1988; SIC 3792) | KOOLON CORP (1990; SIC 3792) | U34: HENDERSON MANUFACTURING CO (1983) | BARRELS KOOLON CORP (1988) | KOOLON CORP (1990) | V34: printed
A35: S04480 | B35: Not on any list | C35: high | D35: 10983 LEROY OR | E35: NORTHGLENN | F35: Adams | G35: 80233 | H35: 39.895961 | I35: -104.96372 | J35: address | K35: Fabricated metals | M35: 1983 | N35: 1990 | O35: 1983;1990 | P35: 2 | Q35: 1 | R35: 1 | S35: 1967 | T35: NEXUS CORPORATION (1983-1990; SIC 3448) | U35: NEXUS CORPORATION (1983) | V35: printed | AD35: ATLAS ROOFING CORPORATION | AE35: 107 | AF35: O'MERA FLEET SERVICES | AG35: 77
A36: S04481 | B36: Not on any list | C36: high | D36: 11060 IRMA ORIVE | E36: NORTHGLENN | F36: Adams | G36: 80233 | H36: 39.897192 | I36: -104.96632 | J36: address | K36: Rubber & plastics | M36: 1983 | N36: 1992 | O36: 1983;1988 | P36: 4 | Q36: 2 | R36: 2 | S36: 1967 | T36: PRECISION PLASTICS CORP (1983; SIC 3079,3642) | BAXTER PHARMASEAL (1988; SIC 3089,3842) | U36: PRECISION PLASTICS CORP (1983) | BAXTER PHARMASEAL (1988) | V36: printed | AF36: CARSTAR IDEAL NORTHGLENN | AG36: 67
A37: S04744 | B37: Not on any list | C37: high | D37: 4920 ALCOTT ST | E37: DENVER | F37: Adams | G37: 80221 | H37: 39.785987 | I37: -105.01699 | J37: address | K37: Fabricated metals; Industrial machinery | M37: 1983 | N37: 1983 | O37: 1983 | P37: 1 | Q37: 1 | R37: 1 | S37: 1962 | T37: O + A MACHINE TOOL INC. (1983; SIC 3429,3599,3842) | U37: O + A MACHINE TOOL INC. (1983) | V37: printed | AF37: HUD CLEANUP ENVIRONET INC | AG37: 100
A38: S05295 | B38: Not on any list | C38: high | D38: 684 DEARBORN ST | E38: AURORA | F38: Adams | G38: 80011 | H38: 39.726885 | I38: -104.81523 | J38: address | K38: Fabricated metals | M38: 1988 | N38: 1990 | O38: 1988;1990 | P38: 2 | Q38: 2 | R38: 2 | S38: 1983 | T38: EDUCATIONAL SOPTWAR LIGHT TOUCH (1988; SIC 3479,3983) | LIGHT TOUCH (1990; SIC 3479) | U38: EDUCATIONAL SOPTWAR LIGHT TOUCH (1988) | LIGHT TOUCH (1990) | V38: printed
A39: S05386 | B39: Not on any list | C39: high | D39: 1150 BRIGHTON RD | E39: BRIGHTON | F39: Adams | G39: 80601 | H39: 39.965089 | I39: -104.83215 | J39: address | K39: Transportation equipment | M39: 1988 | N39: 1990 | O39: 1988;1990 | P39: 2 | Q39: 2 | R39: 2 | S39: 1970 | T39: MANUFACTURIN HALLMARK MFG INC (1988; SIC 2451,3792) | HALLMARK MANUFACTURING INC (1990; SIC 2451,3792) | U39: MANUFACTURIN HALLMARK MFG INC (1988) | HALLMARK MANUFACTURING INC (1990) | V39: printed
A40: S05515 | B40: Not on any list | C40: high | D40: 8570 VALENTIA ST | E40: COMMERCE CITY | F40: Adams | G40: 80022 | H40: 39.851598 | I40: -104.89117 | J40: address | K40: Industrial machinery | M40: 1988 | N40: 1992 | O40: 1988;1990;1992 | P40: 3 | Q40: 1 | R40: 1 | S40: 1978 | T40: CDM MACHINING+FABRICATI (1988-1992; SIC 3689,3564) | U40: CDM MACHINING+FABRICATI (1988) | V40: printed
...

Sheet All F&E hazardous sites
A1: site_id | B1: radar | C1: confidence | D1: address | E1: city | F1: county | G1: zip | H1: lat | I1: lon | J1: geo_level | K1: fe_sectors | L1: ext_sectors | M1: first_year | N1: last_year | O1: hazard_years | P1: n_editions | Q1: n_establishments | R1: n_hazard_establishments | S1: earliest_est | T1: hazard_firms | U1: all_firms | V1: industry_evidence | W1: cleanup_match | X1: tri_match | Y1: rcra_handler_match | Z1: solid_waste_match | AA1: other_epa_match | AB1: cleanup_nearest | AC1: cleanup_nearest_m | AD1: tri_nearest | AE1: tri_nearest_m | AF1: rcra_handler_nearest | AG1: rcra_handler_nearest_m
A2: S00260 | B2: Cleanup / contamination list | C2: medium | D2: 2101 52ND AVE | E2: DENVER | F2: Adams | H2: 39.791055 | I2: -105.01237 | J2: address_approx | K2: Chemicals | M2: 1965 | N2: 1965 | O2: 1965 | P2: 1 | Q2: 1 | R2: 1 | T2: MASTERCRAFT, INC. (1965; SIC 2814) | U2: MASTERCRAFT, INC. (1965) | V2: printed | W2: ADAMS COUNTY ODOR [FRS; 105 m] | Y2: HADLEY AUTO TRANSPORT [CDPHE RCRA; 18 m] | PICK YOUR PART CENTRAL LLC [CDPHE RCRA; 215 m] | RED GIANT OIL COMPANY LLC [CDPHE RCRA; 215 m] | AA2: CLEARWATER ENVIRONMENTAL, INC. [FRS; 62 m] | ZUNI RESIDENCES [FRS; 243 m] | AB2: ADAMS COUNTY ODOR | AC2: 106 | AF2: HADLEY AUTO TRANSPORT | AG2: 19
A3: S00570 | B3: Cleanup / contamination list | C3: high | D3: 5460 COLORADO BLVO | E3: COMMERCE CITY | F3: Adams | G3: 80022 | H3: 39.793832 | I3: -104.93859 | J3: address | K3: Fabricated metals; Industrial machinery; Rubber & plastics | M3: 1966 | N3: 1988 | O3: 1973;1974;1977;1980;1988 | P3: 7 | Q3: 3 | R3: 2 | S3: 1937 | T3: UNION SUPPLY CO (1973-1980; SIC 3496,3293,3535) | FOAM FABRICATORS INC (1988; SIC 3086) | U3: HOGENSON CONCRETE CO (1966) | UNION SUPPLY CO (1973) | FOAM FABRICATORS INC (1988) | V3: printed | W3: Sand Creek/SND [CDPHE CDPHE Superfund] (inside site boundary) | Y3: BARTON SUPPLY [FRS; 33 m] | NEVCO SERVICES INC. [FRS; 39 m] | MASTER WASH [FRS; 39 m] | JCB PRECISION TOOL & MOLD [FRS; 42 m] | AA3: HARRIS REBAR SALT LAKE INC [FRS; 33 m] | AB3: GATES STEEL CO | AC3: 101 | AF3: BARTON SUPPLY | AG3: 33
A4: S00571 | B4: Cleanup / contamination list | C4: high | D4: 5315 VASQUEZ BLVD | E4: COMMERCE CITY | F4: Adams | G4: 80022 | H4: 39.793287 | I4: -104.93947 | J4: address | K4: Industrial machinery; Transportation equipment | M4: 1966 | N4: 1990 | O4: 1966;1968;1970;1973;1974;1980;1983;1988 | P4: 9 | Q4: 8 | R4: 5 | S4: 1958 | T4: INTERSTATE MFG INC (1966-1974; SIC 3523) | CLEARFIELO MANUFACTURING INC (1968; SIC 3535) | AEROMOTIVE METAL PRODUCTS INC (1970-1973; SIC 3799,3714) | INTERMOUNTAIN WHOLESALE, INC (1973-1988; SIC 3523) | PART-CO MACHINE INC (1973; SIC 3591) | U4: INTERSTATE MFG INC (1966) | CLEARFIELO MANUFACTURING INC (1968) | INTERSTATE MFG INC RH KYLLC PRES (1968) | AEROMOTIVE METAL PRODUCTS INC (1970) | INTERMOUNTAIN WHOLESALE, INC (1973) | PART-CO MACHINE INC (1973) | WESTERN TURNINGS * SPECIALTY CO (1980) | R W SPECIALITIES INC (1983) | V4: printed | W4: GATES STEEL CO [FRS; 74 m] | Sand Creek/SND [CDPHE CDPHE Superfund] (inside site boundary) | Y4: THE WASHOP [FRS; 39 m] | AB4: GATES STEEL CO | AC4: 74 | AF4: THE WASHOP | AG4: 39
A5: S00573 | B5: Cleanup / contamination list | C5: high | D5: 5001 E 52ND AVE | E5: COMMERCE CITY | F5: Adams | G5: 80022 | H5: 39.791038 | I5: -104.92946 | J5: address | K5: Industrial machinery | M5: 1966 | N5: 1968 | O5: 1967 | P5: 3 | Q5: 3 | R5: 1 | S5: 1955 | T5: MAK*S SUPPLY CO (1967; SIC 3519) | U5: M+ K MFG CO INC (1966) | MAK*S SUPPLY CO (1967) | MAK'S SUPPLY CO 3581 AUTOMATIC MERCHANDISING MACHINES (1968) | V5: printed | W5: Sand Creek/SND [CDPHE CDPHE Superfund] (inside site boundary) | AA5: COLORADO BRAKE & SUPPLY CO [FRS; 34 m] | COLORADO BRAKE & SUPPLY CO [FRS] (address match) | AB5: Sand Creek/SND | AC5: 180 | AF5: FIVE STAR CHEMICALS & SUPPLY | AG5: 124
A6: S00574 | B6: Cleanup / contamination list | C6: high | D6: 5961 E 64TH AVE | E6: COMMERCE CITY | F6: Adams | G6: 80022 | H6: 39.812847 | I6: -104.91865 | J6: address | K6: Transportation equipment | M6: 1966 | N6: 1992 | O6: 1966;1974;1977 | P6: 6 | Q6: 2 | R6: 1 | S6: 1959 | T6: MITCHELL AND SUNS INC (1966-1977; SIC 3714) | U6: MITCHELL AND SUNS INC (1966) | DENVER WINDOW CORP (1992) | V6: printed | W6: Chemical Sales/CSC [CDPHE CDPHE Superfund] (inside site boundary) | Y6: CVS PHARMACY #COCOM1B01 [FRS; 4 m] | CVS PHARMACY #COCOM1B01 [CDPHE RCRA; 25 m] | FAMILY DOLLAR #9094 [FRS; 26 m] | AF6: CVS PHARMACY #COCOM1B01 | AG6: 5
A7: S00576 | B7: Cleanup / contamination list | C7: high | D7: 6326 IVY | E7: COMMERCE CITY | F7: Adams | G7: 80022 | H7: 39.812385 | I7: -104.91991 | J7: address | K7: Petroleum refining | L7: Asphalt paving mixtures | M7: 1966 | N7: 1980 | O7: 1967 | P7: 6 | Q7: 2 | R7: 1 | S7: 1938 | T7: TAUCHE'S BAKERY 3272 MISC CONCRETE PRODUCTS (1967; SIC 2951) | U7: TAUCHE'S BAKERY (1966) | TAUCHE'S BAKERY 3272 MISC CONCRETE PRODUCTS (1967) | V7: printed | W7: Chemical Sales/CSC [CDPHE CDPHE Superfund] (inside site boundary) | AD7: DPC INDUSTRIES INC | AE7: 213 | AF7: PERFECTA CLNRS | AG7: 51
A8: S00577 | B8: Cleanup / contamination list | C8: high | D8: 5321 DAHLIA ST | E8: COMMERCE CITY | F8: Adams | G8: 80022 | H8: 39.792208 | I8: -104.93165 | J8: address | K8: Chemicals; Fabricated metals; Transportation equipment | L8: Metal mining / ore milling | M8: 1966 | N8: 1990 | O8: 1966;1967;1970;1973;1974;1980;1983;1990 | P8: 8 | Q8: 6 | R8: 6 | S8: 1951 | T8: TIME CHEMICAL CORP (1966; SIC 1035) | COLORACO INTERNATIONAL CORP (1967-1970; SIC 2872) | HAINS ENGINEERING CORP (1973-1974; SIC 3443,3498) | COLORADO ORGANIC CHEMICAL CO INC (1980-1983; SIC 2874,2879) | 8 + D BRAKE SUPPLY CO INC (1983; SIC 3714) | CHEN-REAL INVESTMENT CORP (1990; SIC 2819) | U8: TIME CHEMICAL CORP (1966) | COLORACO INTERNATIONAL CORP (1967) | HAINS ENGINEERING CORP (1973) | COLORADO ORGANIC CHEMICAL CO INC (1980) | 8 + D BRAKE SUPPLY CO INC (1983) | CHEN-REAL INVESTMENT CORP (1990) | V8: printed | W8: COLORADO ORGANIC CHEMICAL SITE/MATTESON WAREHOUSE [FRS; name match, 46 m] | COLORADO ORGANIC CHEMICAL CO INC [FRS; name match, 64 m] | Sand Creek/SND [CDPHE CDPHE Superfund; 49 m] | COLORADO ORGANIC CHEMICAL CO INC [FRS] (address match) | Sand Creek/SND [CDPHE CDPHE Superfund] (inside site boundary) | Y8: WESLEY INDUSTRIES INC. [FRS; 64 m] | WESLEY INDUSTRIES INC. [FRS] (address match) | AA8: CHEM REAL INVESTMENT CORPORATION [FRS; name match, 64 m] | CHEM REAL INVESTMENT CORPORATION [FRS] (address match) | AB8: COLORADO ORGANIC CHEMICAL SITE/MATTESON WAREHOUSE | AC8: 47 | AF8: WESLEY INDUSTRIES INC. | AG8: 65
A9: S00578 | B9: Cleanup / contamination list | C9: medium | D9: 6630 MONACO | E9: COMMERCE CITY | F9: Adams | G9: 80022 | H9: 39.81713 | I9: -104.91281 | J9: address | K9: Transportation equipment | M9: 1966 | N9: 1968 | O9: 1966 | P9: 2 | Q9: 2 | R9: 1 | S9: 1961 | T9: ALUMILUX-SCOTT INC (1966; SIC 3799) | U9: ALUMILUX-SCOTT INC (1966) | (1968) | V9: inferred | W9: Chemical Sales/CSC [CDPHE CDPHE Superfund] (inside site boundary)
A10: S00603 | B10: Cleanup / contamination list | C10: low | D10: 18200 COLFAX | E10: AURORA | F10: Adams | G10: 80011 | H10: 39.740254 | I10: -104.77413 | J10: address_approx | K10: Fabricated metals | M10: 1966 | N10: 1966 | O10: 1966 | P10: 1 | Q10: 1 | R10: 1 | S10: 1961 | T10: AURORA ASPHALT + PAVING CO (1966; SIC 3441) | U10: AURORA ASPHALT + PAVING CO (1966) | V10: inferred | W10: Old Colfax Landfill [CDPHE Voluntary_Cleanup_and_Redevelopment_Program_(VCUP)_new; 212 m] | Colfax Landfill II [CDPHE Voluntary_Cleanup_and_Redevelopment_Program_(VCUP)_new; 212 m] | Y10: U-PULL-AND-PAY LLC [CDPHE RCRA; 118 m] | U-PULL-AND-PAY LLC [FRS; 146 m] | ALL AUTO PARTS [FRS; 182 m] | AA10: 7-ELEVEN INC - 18351 E COLFAX AVE, 36956 [FRS; 53 m] | TRIPLE CREEK TRAILHEAD [FRS; 143 m] | VERIZON WIRELESS - BATAVIA [FRS; 144 m] | COLO DEPT OF HIGHWAYS #5009 [FRS; 144 m] | BUZZ'S AUTO BODY [FRS; 155 m] | HIGH LINE CANAL TRAIL IMPROVEMENTS (COLFAX AVENUE TO I-70) [FRS; 155 m] | BUZZ'S AUTO BODY [FRS; 175 m] | CORVETTE CITY [FRS; 175 m] | METAL MOVERS ZENO [FRS; 175 m] | KOA REGION 1 SITE IMPR | AB10: Old Colfax Landfill | AC10: 213 | AF10: U-PULL-AND-PAY LLC | AG10: 119
A11: S00741 | B11: Cleanup / contamination list | C11: high | D11: 4400 E 61ST AVE | E11: COMMERCE CITY | F11: Adams | G11: 80022 | H11: 39.807245 | I11: -104.93484 | J11: address | K11: Fabricated metals | M11: 1966 | N11: 1990 | O11: 1966;1967;1968;1970;1973;1974;1990 | P11: 7 | Q11: 2 | R11: 2 | S11: 1955 | T11: BOYLES GALVANIZING + PLATING CO (1966; SIC 3496) | BOYLES GALVANIZING + PLATING CO (1967-1990; SIC 3479,3481) | U11: BOYLES GALVANIZING + PLATING CO (1966) | BOYLES GALVANIZING + PLATING CO (1967) | V11: printed | W11: N.A. GALVANIZING CO - 4400 E 61ST AVE [FRS] (address match) | X11: AZZ GALVANIZING -DENVER [TRI] (address match) | Y11: AZZ GALVANIZING SERVICES - DENVER [CDPHE RCRA] (address match) | AA11: AZZ INC. [FRS] (address match) | AB11: N.A. GALVANIZING CO - 4400 E 61ST AVE | AC11: 142 | AD11: HYDROGATE ACQUISITION CORP | AE11: 233 | AF11: CORNERSTON COATINGS / CLERMONT PRODUCTION FACILITY | AG11: 42
A12: S01000 | B12: Cleanup / contamination list | C12: high | D12: 5901 FEDERAL BLVO | E12: DENVER | F12: Adams | G12: 80221 | H12: 39.80406 | I12: -105.02539 | J12: address | K12: Petroleum refining | M12: 1966 | N12: 1974 | O12: 1966;1970;1973;1974 | P12: 4 | Q12: 1 | R12: 1 | S12: 1933 | T12: WILLIAMS REFINING CO (1966-1974; SIC 2911) | U12: WILLIAMS REFINING CO (1966) | V12: printed | W12: ENGLAND WATER TREATMENT PLANT [FRS; 13 m] | 5900 FEDERAL [FRS; 55 m] | AA12: W 60 AVE IMPROVEMENTS [FRS; 34 m] | AB12: ENGLAND WATER TREATMENT PLANT | AC12: 14 | AF12: CUNNINGHAM PROPERTY | AG12: 55
A13: S01318 | B13: Cleanup / contamination list | C13: high | D13: 4801 MONACO | E13: COMMERCE CITY | F13: Adams | G13: 80022 | H13: 39.783818 | I13: -104.91289 | J13: address | K13: Industrial machinery | M13: 1967 | N13: 1983 | O13: 1967 | P13: 7 | Q13: 4 | R13: 1 | S13: 1951 | T13: AEON PRECISION CO (1967; SIC 3542,3544) | U13: AEON PRECISION CO (1967) | BARON PRINT INC (1967) | BARON PRENT ENC (1980) | LICHT EDITIONS LTD (1983) | V13: printed | W13: Chemical Sales/CSC [CDPHE CDPHE Superfund] (inside site boundary) | AB13: MESA FIBERGLASS PROD CO | AC13: 167 | AD13: MESA FIBERGLASS INC.CN | AE13: 161 | AF13: YUASA EXIDE | AG13: 104
A14: S01326 | B14: Cleanup / contamination list | C14: medium | D14: 5350 N FEDERAL BLVD | E14: DENVER | F14: Adams | G14: 80221 | H14: 39.794373 | I14: -105.02515 | J14: address_approx | K14: Fabricated metals | M14: 1967 | N14: 1970 | O14: 1967;1968;1970 | P14: 3 | Q14: 1 | R14: 1 | S14: 1965 | T14: FAMILY RECREATION + SUPPLY CO (1967-1970; SIC 3429,3949) | U14: FAMILY RECREATION + SUPPLY CO (1967) | V14: printed | W14: 53RD & FEDERAL [FRS; 139 m] | Marycrest Assisted Living [CDPHE Voluntary_Cleanup_and_Redevelopment_Program_(VCUP)_new; 184 m] | Y14: MUNOZ AUTO [FRS; 16 m] | DERRY AUTO BODY [FRS; 72 m] | PRO STREET RODS [FRS; 117 m] | FAMILY DOLLAR #8668 [FRS; 121 m] | ADVANCED AUTO [FRS; 214 m] | AA14: ARIA NW DETENTION POND [FRS; 44 m] | MARYCREST HIGH SCHOOL [FRS; 106 m] | SUPREME TOUCH AUTO BODY [FRS; 117 m] | CR 2 VEHICLES CO DAVE BROOKS AUTO (ADAMS [FRS; 117 m] | DERRY ENTERPRISES INC [FRS; 117 m] | HERMOSA VETERINARY CLINIC [FRS; 145 m] | EMMANS HOUSE [FRS; 203 m] | 3075 W. 53RD AVE. MINOR SUBDIVISION [FRS; 210 m] | AB14: 53RD & FEDERAL | AC14: 139 | AF14: MUNOZ AUTO | AG14: 17
A15: S01649 | B15: Cleanup / contamination list | C15: high | D15: 4950 NIAGARA | E15: COMMERCE CITY | F15: Adams | G15: 80022 | H15: 39.786304 | I15: -104.91126 | J15: address | K15: Industrial machinery; Rubber & plastics | M15: 1968 | N15: 1983 | O15: 1968;1970;1973;1974;1980 | P15: 6 | Q15: 3 | R15: 2 | S15: 1966 | T15: c OM TOOL + CIE (1968-1980; SIC 3544) | UsS- POLYGLASS (1973; SIC 3079) | U15: c OM TOOL + CIE (1968) | UsS- POLYGLASS (1973) | AUSTRO FURNITURE CO (1983) | V15: printed | W15: CDM MACHINING AND FABRICATION [FRS; 6 m] | Chemical Sales/CSC [CDPHE CDPHE Superfund] (inside site boundary) | AB15: CDM MACHINING AND FABRICATION | AC15: 6 | AD15: FIVE STAR AFFILIATES | AE15: 132 | AF15: DENVER IRON WORKS | AG15: 103
A16: S01654 | B16: Cleanup / contamination list | C16: high | D16: 8810 LANDER | E16: WESTMINSTER | F16: Adams | G16: 80030 | H16: 39.85643 | I16: -105.03335 | J16: address | K16: Chemicals; Petroleum refining | M16: 1968 | N16: 1990 | O16: 1968;1973;1983;1988;1990 | P16: 5 | Q16: 4 | R16: 4 | S16: 1956 | T16: OIAMON GLOW CC (1968; SIC 2842,2051) | DIAMON GLOW CO (1973-1990; SIC 2899,2842,2051) | DIAMOND GLOW WATCHEJLRY.CLEANSFLUIDS CO (1983; SIC 2842) | D.B.A.-RESEARCH CHEMICAL WEStMINGTES ADAMS (1988; SIC 2842,2992) | U16: OIAMON GLOW CC (1968) | DIAMON GLOW CO (1973) | DIAMOND GLOW WATCHEJLRY.CLEANSFLUIDS CO (1983) | D.B.A.-RESEARCH CHEMICAL WEStMINGTES ADAMS (1988) | V16: printed | W16: SHAW HEIGHTS CLEANERS [CDPHE Institutional_Controls_PROD_local; 89 m] | SHAW HEIGHTS CLEANERS [CDPHE Institutional_Controls_PROD_local] (inside site boundary) | AB16: SHAW HEIGHTS CLEANERS | AC16: 89 | AF16: SHAW HEIGHTS CLEANERS | AG16: 205
A17: S01820 | B17: Cleanup / contamination list | C17: high | D17: 1170 W 46TH | E17: DENVER | F17: Adams | G17: 80221 | H17: 39.780163 | I17: -105.00153 | J17: address | K17: Rubber & plastics | M17: 1968 | N17: 1983 | O17: 1983 | P17: 3 | Q17: 2 | R17: 1 | S17: 1959 | T17: R MT PLASTICS (1983; SIC 2599,3079,2449) | U17: TASTY FCODS INC (1968) | R MT PLASTICS (1983) | V17: printed | W17: RAMP IND INC [FRS; 33 m] | AA17: AMRP HIGHLANDS 10 MW IP RENEWAL [FRS; 20 m] | AB17: RAMP IND INC | AC17: 33 | AD17: DAWN FOODS PRODUCTS | AE17: 149 | AF17: HUSKAR | AG17: 92
A18: S01971 | B18: Cleanup / contamination list | C18: high | D18: 8200 E 96TH AVE | E18: HENDERSON | F18: Adams | G18: 80640 | H18: 39.870612 | I18: -104.89439 | J18: address | K18: Transportation equipment | M18: 1970 | N18: 1983 | O18: 1970;1973;1980;1983 | P18: 4 | Q18: 3 | R18: 3 | S18: 1957 | T18: BEALL TRANSPORT EQUIPMENT SALES CO (1970; SIC 3715) | BEALL EQUIPMENT CORP OF COLORADO (1973; SIC 3715) | TEMPTE-BEALL, INC (1980-1983; SIC 3799) | U18: BEALL TRANSPORT EQUIPMENT SALES CO (1970) | BEALL EQUIPMENT CORP OF COLORADO (1973) | TEMPTE-BEALL, INC (1980) | V18: printed | W18: TIMPTE-BEALL INC [FRS] (address match) | X18: REBAR COATING & FABRICATION [FRS; 97 m] | DENVER ARCHITECHURAL PRECAST INC [FRS] (address match) | DENVER ARCHITECTURAL PRECAST INC [TRI] (address match) | AA18: HOLCIM (US), INC. [FRS; 22 m] | AD18: REBAR COATING & FABRICATION | AE18: 98 | AF18: CUMMINS INC - HENDERSON BRANCH | AG18: 152
A19: S02233 | B19: Cleanup / contamination list | C19: high | D19: 6525 WASHINGTON ST N | E19: THORNTON | F19: Adams | G19: 80229 | H19: 39.81518 | I19: -104.97805 | J19: address | K19: Fabricated metals; Industrial machinery; Petroleum refining | L19: Electronic components | M19: 1970 | N19: 1990 | O19: 1970;1973;1974;1977;1980;1983;1988;1990 | P19: 8 | Q19: 10 | R19: 7 | S19: 1967 | T19: JET PRECISION INC (1970-1974; SIC 3461,3444) | JET PRECISION INC T J PRICE MKTG DIR (1973; SIC 3469) | WESTERN SALES + SUPPLY CO (1973-1974; SIC 3589,3949,3451) | ARROW SHEET METAL PRODUCTS CO (1977; SIC 3444) | CRYOGENIC ENERGY CORP (1980-1983; SIC 3443,3559) | SARAS EES Rc (1988; SIC 2431,3679,2901) | GARAGE DOOR SPECIALTIES INC (1990; SIC 2431,3679) | U19: JET PRECISION INC (1970) | JET PRECISION INC T J PRICE MKTG DIR (1973) | WESTERN SALES + SUPPLY CO (1973) | DESIGN MANUFACTURING INC (1974) | ARROW SHEET METAL PRODUCTS CO (1977) | CARSON CONCRETE CASTING CO INC (1977) | CRYOGENIC ENERGY CORP (1980) | QUALITY COUNTER TOPS INC (1980) | SARAS EES Rc (1988) | GARAGE DOOR SPECIALTIES INC (1990) | V19: printed | W19: JWBSK INC. DBA WEAVER ELECTRIC COMPANY [FRS; 96 m] | X19: CRYENCO INC [FRS; 1 m] | REGION 8 ENVIRO LLC - UNIT K [FRS; 4 m] | Y19: PRECISION PIPE SERVICES LLC [FRS; 3 m] | MAVERICK BIOFUELS, INC. - M2 FACILITY [FRS; 3 m] | WESTERN FREIGHTWAYS INC [FRS; 18 m] | BUFFALO EXPRESS INC [FRS; 18 m] | AA19: MILLER BROTHERS INC [FRS; 18 m] | AB19: JWBSK INC. DBA WEAVER ELECTRIC COMPANY | AC19: 97 | AD19: CRYENCO INC | AE19: 1 | AF19: PRECISION PIPE SERVICES LLC | AG19: 3
A20: S02193 | B20: Cleanup / contamination list | C20: high | D20: 6348 HOLLY | E20: COMMERCE CITY | F20: Adams | G20: 80022 | H20: 39.811873 | I20: -104.9222 | J20: address | K20: Fabricated metals; Transportation equipment | M20: 1973 | N20: 1973 | O20: 1973 | P20: 1 | Q20: 1 | R20: 1 | S20: 1967 | T20: ALLANS ENTERPRISES (1973; SIC 3714,3446) | U20: ALLANS ENTERPRISES (1973) | V20: printed | W20: Former Commerce City Dog Track/CDT [CDPHE Institutional_Controls_PROD_local] (inside site boundary) | Chemical Sales/CSC [CDPHE CDPHE Superfund] (inside site boundary) | X20: DPC INDUSTRIES INC [TRI; 22 m] | AD20: DPC INDUSTRIES INC | AE20: 23 | AF20: ALBERT FREI & SONS INC | AG20: 91
A21: S02203 | B21: Cleanup / contamination list | C21: high | D21: 5155 E 64TH AVE | E21: COMMERCE CITY | F21: Adams | G21: 80022 | H21: 39.812801 | I21: -104.92738 | J21: address | K21: Transportation equipment | M21: 1973 | N21: 1974 | O21: 1973;1974 | P21: 2 | Q21: 1 | R21: 1 | T21: GREAT DIVIDE COACH MFG CO (1973-1974; SIC 3792) | U21: GREAT DIVIDE COACH MFG CO (1973) | V21: printed | W21: Former Commerce City Dog Track/CDT [CDPHE Institutional_Controls_PROD_local] (inside site boundary) | AB21: Former Commerce City Dog Track/CDT | AC21: 240
A22: S02204 | B22: Cleanup / contamination list | C22: high | D22: 5591 LEYDEN | E22: COMMERCE CITY | F22: Adams | G22: 80022 | H22: 39.798206 | I22: -104.91574 | J22: address | K22: Fabricated metals | M22: 1973 | N22: 1988 | O22: 1973;1977;1988 | P22: 4 | Q22: 3 | R22: 2 | S22: 1954 | T22: KK TROPHIES INC (1973-1977; SIC 3499,2499) | SURFAS MFG+SUPPLY (1988; SIC 3482,3849) | U22: KK TROPHIES INC (1973) | SURFAS HFG * SUPPLY 2387 BEADED BELTS (1983) | SURFAS MFG+SUPPLY (1988) | V22: printed | W22: Chemical Sales/CSC [CDPHE CDPHE Superfund] (inside site boundary) | Y22: SEDITA MANUFACTURING [FRS; 38 m] | AA22: MOUNTAIN MARINE INDUSTRIES, INC. [FRS; 18 m] | AB22: CURTIS LANDSCAPING | AC22: 111 | AF22: SEDITA MANUFACTURING | AG22: 38
A23: S02209 | B23: Cleanup / contamination list | C23: medium | D23: 4100 E 60TH AVE | E23: COMMERCE CITY | F23: Adams | G23: 80022 | H23: 39.805616 | I23: -104.94111 | J23: address_approx | K23: Industrial machinery | M23: 1973 | N23: 1990 | O23: 1973;1974;1977;1980;1983;1990 | P23: 6 | Q23: 1 | R23: 1 | S23: 1946 | T23: MACHINE LABORATORY (1973-1990; SIC 3591) | U23: MACHINE LABORATORY (1973) | V23: printed | W23: WEAVER ELECTRIC LOT #2 [FRS; 95 m] | SUNCOR REFINERY YELLOW PLUME [FRS; 192 m] | Y23: D&R TRANSFER STATION - WASTE MANAGEMENT OF COLORADO INC [CDPHE RCRA; 166 m] | D&R TRANSFER STATION - WASTE MANAGEMENT OF COLORADO INC [FRS; 166 m] | RTD NORTH METRO RAIL LINE PROJECT [FRS; 179 m] | BETZDEARBORN INC [FRS; 179 m] | DENVER OIL LLC [FRS] (address match) | DENVER OIL LLC [CDPHE RCRA] (address match) | AA23: 4150 E. 60TH AVE [FRS; 86 m] | 4150 E 60TH AVE [FRS; 86 m] | COMMERCE CITY DISPOSAL AND RECYCLING TRANSFER STATION [FRS; 165 m] | WASTE MANAGEMENT OF COLORADO [FRS; 165 m] | GEM MOBILE [FRS; 179 m] | DENVER WEST [FRS; 179 m] | DENVER TERMINAL [FRS; 179 m] | DENVER EAST [FRS; 179 m] | SCBW SUBSURFACE BARRIER WALL INSTALLATION [FRS; 179 m] | DENVER RAIL [FRS; 179 m] | DENVER REFINERY [FRS; 179 m] | | AB23: WEAVER ELECTRIC LOT #2 | AC23: 96 | AF23: D&R TRANSFER STATION - WASTE MANAGEMENT OF COLORADO INC | AG23: 166
A24: S02212 | B24: Cleanup / contamination list | C24: high | D24: 6421 E 49 OR | E24: COMMERCE CITY | F24: Adams | G24: 80022 | H24: 39.78523 | I24: -104.91415 | J24: address | K24: Rubber & plastics | M24: 1973 | N24: 1977 | O24: 1973;1974;1977 | P24: 3 | Q24: 2 | R24: 2 | S24: 1972 | T24: SILL-MAR MFG CO (1973-1977; SIC 3079) | QUAD-B INC (1977; SIC 3079) | U24: SILL-MAR MFG CO (1973) | QUAD-B INC (1977) | V24: printed | W24: MESA FIBERGLASS PROD CO [FRS; 47 m] | Chemical Sales/CSC [CDPHE CDPHE Superfund] (inside site boundary) | X24: MESA FIBERGLASS INC.CN [FRS; 68 m] | Y24: COMMERCE CITY SHOP [FRS; 14 m] | ELITE AUTO BODY II [FRS; 15 m] | AB24: MESA FIBERGLASS PROD CO | AC24: 47 | AD24: MESA FIBERGLASS INC.CN | AE24: 68 | AF24: COMMERCE CITY SHOP | AG24: 15
A25: S02213 | B25: Cleanup / contamination list | C25: high | D25: 4306 E 60TH AVE | E25: COMMERCE CITY | F25: Adams | G25: 80022 | H25: 39.805086 | I25: -104.93788 | J25: address | K25: Petroleum refining | L25: Asphalt paving mixtures | M25: 1973 | N25: 1990 | O25: 1973;1974;1977;1980;1988;1990 | P25: 6 | Q25: 1 | R25: 1 | S25: 1964 | T25: UNITED ASPHALTS INC (1973-1990; SIC 2952) | U25: UNITED ASPHALTS INC (1973) | V25: printed | W25: UNITED ASPHALTS - 4306 E 60TH AVE [FRS; name match, 175 m] | UNITED ASPHALTS - 4306 E 60TH AVE [FRS] (address match) | X25: BKEP MATERIALS - DENVER C & K [FRS; 90 m] | AB25: UNITED ASPHALTS - 4306 E 60TH AVE | AC25: 176 | AD25: BKEP MATERIALS - DENVER C & K | AE25: 91 | AF25: PROTECH BUILDING SERVICES | AG25: 77
A26: S02214 | B26: Cleanup / contamination list | C26: high | D26: 4945 MONACO | E26: COMMERCE CITY | F26: Adams | G26: 80022 | H26: 39.786226 | I26: -104.91288 | J26: address | K26: Fabricated metals; Rubber & plastics | M26: 1973 | N26: 1990 | O26: 1973;1974;1977;1990 | P26: 5 | Q26: 3 | R26: 2 | S26: 1967 | T26: WESTERN COMPUTER METAL PRODUCTS, INC (1973-1977; SIC 3499) | WHALE SCIENTIFIC CO (1990; SIC 3089) | U26: WESTERN COMPUTER METAL PRODUCTS, INC (1973) | TELAN CORPORATION (1980) | WHALE SCIENTIFIC CO (1990) | V26: printed | W26: Chemical Sales/CSC [CDPHE CDPHE Superfund] (inside site boundary) | Y26: WHALE SCIENTIFIC INC [FRS; name match, 9 m] | Z26: Sum Computers Inc [CDPHE Solid_Waste_Facilities; 10 m] | AB26: MESA FIBERGLASS PROD CO | AC26: 128 | AD26: MESA FIBERGLASS INC | AE26: 110 | AF26: WHALE SCIENTIFIC INC | AG26: 10
A27: S02229 | B27: Cleanup / contamination list | C27: high | D27: 6066 E 49TH AVE | E27: COMMERCE CITY | F27: Adams | G27: 80022 | H27: 39.785952 | I27: -104.9176 | J27: address | K27: Chemicals; Industrial machinery | M27: 1973 | N27: 1990 | O27: 1973;1988 | P27: 3 | Q27: 3 | R27: 2 | S27: 1970 | T27: SUBTERRANEAN TOOLS» INC (1973; SIC 3532) | ROCKY MTN PRO CLEAN (1988; SIC 2842) | U27: SUBTERRANEAN TOOLS» INC (1973) | ROCKY MTN PRO CLEAN (1988) | THE PILLOW SHOPPE INC (1990) | V27: printed | W27: PRO CLEAN [FRS; name match, 61 m] | PRO CLEAN [FRS] (address match) | Chemical Sales/CSC [CDPHE CDPHE Superfund] (inside site boundary) | Y27: THE PILLOW SHOP [FRS; name match, 42 m] | LAKESHORE INC [FRS; 22 m] | SYSTEMATIC TRADE [FRS; 26 m] | AA27: PILLOW SHOPPE INC DBA COLLIERS OF COLO [FRS; name match, 92 m] | AB27: PRO CLEAN | AC27: 62 | AF27: LAKESHORE INC | AG27: 23
A28: S02746 | B28: Cleanup / contamination list | C28: high | D28: 5390 E 72ND AVE | E28: COMMERCE CITY | F28: Adams | G28: 80022 | H28: 39.827231 | I28: -104.92524 | J28: address | K28: Petroleum refining | M28: 1974 | N28: 1990 | O28: 1974;1977;1990 | P28: 3 | Q28: 2 | R28: 2 | S28: 1965 | T28: CUSTCM REFINING COMPANY (1974-1977; SIC 2992) | MILT ADAMS INC (1990; SIC 2992) | U28: CUSTCM REFINING COMPANY (1974) | MILT ADAMS INC (1990) | V28: printed | W28: MILT ADAMS INC OR APPROVED DRAIN OIL SER [FRS] (address match) | Y28: MAI APPROVED OIL SERVICE INC [FRS; 15 m] | MAI APPROVED OIL SERVICE INC [FRS] (address match) | AA28: BOLD PETROLEUM INC [FRS; 25 m] | COLORADO ASPHALT WORKS, INC [FRS] (address match) | AB28: Approved Oil (N Parcel) | AC28: 217 | AF28: MAI APPROVED OIL SERVICE INC | AG28: 15
A29: S02754 | B29: Cleanup / contamination list | C29: medium | D29: 7777 BRIGHTON RD | E29: DUPONT | F29: Adams | G29: 80024 | H29: 39.837819 | I29: -104.92341 | J29: address_approx | K29: Fabricated metals | M29: 1974 | N29: 1974 | O29: 1974 | P29: 1 | Q29: 1 | R29: 1 | S29: 1970 | T29: COLORADO TORCH INDUSTRIES», INC (1974; SIC 3448,3441) | U29: COLORADO TORCH INDUSTRIES», INC (1974) | V29: printed | W29: Chemical Sales/CSC [CDPHE CDPHE Superfund] (inside site boundary) | Y29: RESOURCE ENVIRONMENTAL GROUP SERVICES [FRS; 80 m] | J C DIESEL [FRS; 165 m] | WESTERN TRUCK PARTS INC [FRS; 208 m] | CONVIENCE PLUS WAREHOUSE [FRS; 239 m] | AA29: KENWOOD OUTFALL STORM SEWER [FRS; 104 m] | WITTMUSS MOBILE HOME PARK [FRS; 143 m] | KENWOOD OUTFALL PH III [FRS; 171 m] | KENWOOD MICROTUNNEL HWY 85 CROSSING [FRS; 181 m] | 76 TO 77 AVE STORM SEWER [FRS; 247 m] | ALLIED DEMO - ALLIED RECYCLED AGGREGATES [FRS; 248 m] | AF29: RESOURCE ENVIRONMENTAL GROUP SERVICES | AG29: 80
A30: S02756 | B30: Cleanup / contamination list | C30: high | D30: 6001 DEXTER | E30: COMMERCE CITY | F30: Adams | G30: 80022 | H30: 39.805509 | I30: -104.93191 | J30: address | K30: Transportation equipment | M30: 1974 | N30: 1974 | O30: 1974 | P30: 1 | Q30: 1 | R30: 1 | S30: 1973 | T30: FLEET EQUIPMENT CO (1974; SIC 3714) | U30: FLEET EQUIPMENT CO (1974) | V30: printed | W30: DEXTER & 60TH [FRS; 2 m] | DEXTER & 60TH [FRS] (address match) | AA30: FORMER CHEVRON SVC STA 7 0273 [FRS; 2 m] | 25826 SH 2 (VASQUEZ) AND 60TH AVENUE [FRS; 21 m] | AB30: DEXTER & 60TH | AC30: 3 | AF30: 6025/6075 PARKWAY DR (VACANT FIELD) | AG30: 95
A31: S02757 | B31: Cleanup / contamination list | C31: medium | D31: 5253 GRAPE CRIVE | E31: COMMERCE CITY | F31: Adams | G31: 80022 | H31: 39.894633 | I31: -104.92462 | J31: address_approx | K31: Rubber & plastics | M31: 1974 | N31: 1988 | O31: 1974;1980 | P31: 3 | Q31: 2 | R31: 1 | S31: 1963 | T31: INTERMCUNTAIN RUBBER INDUSTRIES (1974-1980; SIC 3069) | U31: INTERMCUNTAIN RUBBER INDUSTRIES (1974) | PRECAST BUILDING SYSTEMS INC (1988) | V31: printed | W31: BISHOP [FRS; 15 m] | AA31: RIVERDALE POINTE [FRS; 148 m] | AB31: BISHOP | AC31: 15
A32: S02760 | B32: Cleanup / contamination list | C32: high | D32: 5870 E 56TH | E32: COMMERCE CITY | F32: Adams | G32: 80022 | H32: 39.798343 | I32: -104.92021 | J32: address | K32: Fabricated metals; Rubber & plastics | L32: Semiconductors | M32: 1974 | N32: 1992 | O32: 1974;1977;1988;1990;1992 | P32: 5 | Q32: 2 | R32: 2 | S32: 1948 | T32: STANDARD METAL FABR (1974-1977; SIC 3444) | WATERSAVER CO INC (1988-1992; SIC 3069,3089,3433) | U32: STANDARD METAL FABR (1974) | WATERSAVER CO INC (1988) | V32: printed | W32: Chemical Sales/CSC [CDPHE CDPHE Superfund] (inside site boundary) | X32: A R WILFLEY & SONS INC [FRS; 45 m] | AA32: WATERSAVER CO INC [FRS; name match, 45 m] | ORIBI MANUFACTURING [FRS; 19 m] | AB32: FRANZEN AND SONS | AC32: 197 | AD32: A R WILFLEY & SONS INC | AE32: 45 | AF32: APPLIED CONTROL EQUIPMENT LLLP | AG32: 83
A33: S02764 | B33: Cleanup / contamination list | C33: high | D33: 4915 NIAGARA | E33: COMMERCE CITY | F33: Adams | G33: 80022 | H33: 39.785554 | I33: -104.91125 | J33: address | K33: Fabricated metals; Industrial machinery; Rubber & plastics | M33: 1974 | N33: 1988 | O33: 1980;1988 | P33: 3 | Q33: 3 | R33: 2 | S33: 1971 | T33: CONNOR SPRING + MANUFACTURING CO (1980; SIC 3495,3469,3496) | ACCESSORIES TFICO (1988; SIC 3084,3089,3864) | U33: WHATLEY W J INC (1974) | CONNOR SPRING + MANUFACTURING CO (1980) | ACCESSORIES TFICO (1988) | V33: printed | W33: Chemical Sales/CSC [CDPHE CDPHE Superfund] (inside site boundary) | AA33: THERMOPLASTIC FABRICATIONS INC [FRS; 11 m] | AB33: CDM MACHINING AND FABRICATION | AC33: 77 | AD33: MESA FIBERGLASS INC | AE33: 111 | AF33: KNIGHT PRINTING CO | AG33: 59
A34: S02922 | B34: Cleanup / contamination list | C34: medium | D34: 431 W 84TH AVE | E34: DENVER | F34: Adams | G34: 80221 | H34: 39.84907 | I34: -104.99261 | J34: address_approx | K34: Fabricated metals | M34: 1974 | N34: 1990 | O34: 1974;1980;1988;1990 | P34: 4 | Q34: 1 | R34: 1 | S34: 1958 | T34: KNERL SHEET METAL INC (1974-1990; SIC 3444) | U34: KNERL SHEET METAL INC (1974) | V34: printed | W34: ECONO LUBE N TUNE # 206 [FRS; 32 m] | Y34: SEARS ROEBUCK & CO. [FRS; 111 m] | IMAGE CLEANERS [FRS; 169 m] | ACCUPRINT [FRS; 232 m] | AA34: MIDWEST HAULERS INC [FRS; 61 m] | NORTH STAR PRINTING [FRS; 78 m] | ENERGY TECHNOLOGIES GROUP, INC. [FRS; 95 m] | BIG RED Q QUICKPRINT [FRS; 232 m] | AB34: ECONO LUBE N TUNE # 206 | AC34: 33 | AF34: SEARS ROEBUCK & CO. | AG34: 111
A35: S03185 | B35: Cleanup / contamination list | C35: medium | D35: 9700 FAIRFAX | E35: COMMERCE CITY | F35: Adams | G35: 80022 | H35: 39.895795 | I35: -104.92701 | J35: address_approx | K35: Fabricated metals; Industrial machinery | M35: 1977 | N35: 1977 | O35: 1977 | P35: 1 | Q35: 1 | R35: 1 | S35: 1960 | T35: KENDO INCORPORATED (1977; SIC 3531,3441,3599) | U35: KENDO INCORPORATED (1977) | V35: printed | W35: BISHOP [FRS; 247 m] | AB35: BISHOP | AC35: 248
A36: S03187 | B36: Cleanup / contamination list | C36: high | D36: 6471 E 49TH DR | E36: COMMERCE CITY | F36: Adams | G36: 80022 | H36: 39.785231 | I36: -104.91334 | J36: address | K36: Fabricated metals; Industrial machinery; Rubber & plastics | M36: 1977 | N36: 1990 | O36: 1977;1980;1983;1990 | P36: 4 | Q36: 1 | R36: 1 | S36: 1960 | T36: MESA FIBERGLASS PROD CO (1977-1990; SIC 3079) | U36: MESA FIBERGLASS PROD CO (1977) | V36: printed | W36: MESA FIBERGLASS PROD CO [FRS; name match, 22 m] | MESA FIBERGLASS PROD CO [FRS] (address match) | Chemical Sales/CSC [CDPHE CDPHE Superfund] (inside site boundary) | X36: MESA FIBERGLASS INC.CN [FRS; name match, 1 m] | MESA FIBERGLASS INC [TRI; name match, 72 m] | MESA FIBERGLASS INC [TRI] (address match) | Y36: UE COMPRESSION LLC [CDPHE RCRA] (address match) | AA36: PRECISION PIPE & VESSEL, LLC [FRS; 1 m] | U E COMPRESSION 49 DR [FRS; 22 m] | RIDGEATTHORNTONSTATION [FRS; 28 m] | AB36: MESA FIBERGLASS PROD CO | AC36: 22 | AD36: MESA FIBERGLASS INC.CN | AE36: 1 | AF36: ELITE AUTO BODY II | AG36: 53
A37: S03188 | B37: Cleanup / contamination list | C37: high | D37: 8250 PONTIAC | E37: COMMERCE CITY | F37: Adams | G37: 80022 | H37: 39.846051 | I37: -104.90543 | J37: address | K37: Fabricated metals | M37: 1977 | N37: 1977 | O37: 1977 | P37: 1 | Q37: 1 | R37: 1 | S37: 1977 | T37: MOUNTAIN STATES BUILDING PRODUCTS (1977; SIC 3446) | U37: MOUNTAIN STATES BUILDING PRODUCTS (1977) | V37: printed | W37: Chemical Sales/CSC [CDPHE CDPHE Superfund] (inside site boundary) | AF37: COLOGRAPHIC INC. | AG37: 187
A38: S03189 | B38: Cleanup / contamination list | C38: high | D38: 5433 NEWPORT | E38: COMMERCE CITY | F38: Adams | G38: 80022 | H38: 39.796097 | I38: -104.90973 | J38: address | K38: Primary metals | M38: 1977 | N38: 1980 | O38: 1977;1980 | P38: 2 | Q38: 1 | R38: 1 | S38: 1930 | T38: NATIONAL SMELTING + REFINING CO (1977-1980; SIC 3341) | U38: NATIONAL SMELTING + REFINING CO (1977) | V38: printed | W38: Chemical Sales/CSC [CDPHE CDPHE Superfund] (inside site boundary) | Y38: SUPREME AUTOBODY [FRS; 39 m] | AA38: NATL SMELTING & REFINING CO [FRS; name match, 97 m] | AB38: MATHESON TRUCK PARTS & REPAIR | AC38: 117 | AD38: W.J. WHATLEY INC. | AE38: 238 | AF38: SUPREME AUTOBODY | AG38: 39
A39: S03193 | B39: Cleanup / contamination list | C39: high | D39: 6980 E 54TH PL | E39: COMMERCE CITY | F39: Adams | G39: 80022 | H39: 39.795671 | I39: -104.90751 | J39: address | K39: Rubber & plastics | M39: 1977 | N39: 1990 | O39: 1977;1980;1990 | P39: 3 | Q39: 1 | R39: 1 | S39: 1970 | T39: WHATLEYs WJ» INC (1977-1990; SIC 3079,3949) | U39: WHATLEYs WJ» INC (1977) | V39: printed | W39: W J WHATLEY INCORPORATED [FRS; 2 m] | W J WHATLEY INCORPORATED [FRS] (address match) | Chemical Sales/CSC [CDPHE CDPHE Superfund] (inside site boundary) | X39: W.J. WHATLEY INC. [TRI; 45 m] | W.J. WHATLEY INC. [TRI] (address match) | AB39: W J WHATLEY INCORPORATED | AC39: 2 | AD39: W.J. WHATLEY INC. | AE39: 45 | AF39: MATHESON TRUCK PARTS & REPAIR | AG39: 74
A40: S03578 | B40: Cleanup / contamination list | C40: high | D40: 5423 E 52ND AVE | E40: COMMERCE CITY | F40: Adams | G40: 80022 | H40: 39.79106 | I40: -104.92474 | J40: address | K40: Industrial machinery | M40: 1980 | N40: 1980 | O40: 1980 | P40: 1 | Q40: 1 | R40: 1 | S40: 1978 | T40: ADVANTAGE MFG COs INC (1980; SIC 3599,3561,3599) | U40: ADVANTAGE MFG COs INC (1980) | V40: printed | W40: THERMO KING [FRS; 74 m] | Sand Creek/SND [CDPHE CDPHE Superfund] (inside site boundary) | Y40: T R TRUCK REPAIR [FRS; 9 m] | AA40: COMMERCE CITY COLLISION -5421 E 52ND AVE [FRS; 9 m] | EXACTA RUBBER INC [FRS; 13 m] | DENVER CARTAGE COMPANY - DENVER CARTAGE COMPANY - [FRS; 19 m] | AB40: THERMO KING | AC40: 74 | AF40: T R TRUCK REPAIR | AG40: 9
...

Sheet Extended-sector sites
A1: site_id | B1: radar | C1: confidence | D1: address | E1: city | F1: county | G1: zip | H1: lat | I1: lon | J1: geo_level | K1: fe_sectors | L1: ext_sectors | M1: first_year | N1: last_year | O1: hazard_years | P1: n_editions | Q1: n_establishments | R1: n_hazard_establishments | S1: earliest_est | T1: hazard_firms | U1: all_firms | V1: industry_evidence | W1: cleanup_match | X1: tri_match | Y1: rcra_handler_match | Z1: solid_waste_match | AA1: other_epa_match | AB1: cleanup_nearest | AC1: cleanup_nearest_m | AD1: tri_nearest | AE1: tri_nearest_m | AF1: rcra_handler_nearest | AG1: rcra_handler_nearest_m
A2: S07154 | B2: Cleanup / contamination list | C2: high | D2: 3019 W 74TH AVE | E2: WESTMINSTER | F2: Adams | G2: 80030 | H2: 39.830899 | I2: -105.02529 | J2: address | L2: Electronic tubes | M2: 1992 | N2: 1992 | O2: 1992 | P2: 1 | Q2: 1 | R2: 1 | S2: 1989 | T2: DAIRY QUEEN #4 (1992; SIC 2024,3671) | U2: DAIRY QUEEN #4 (1992) | V2: printed | W2: WORLD SAVINGS [FRS; 22 m] | WESTMINSTER PARTNERS [FRS; 23 m] | Y2: SALLY BEAUTY SUPPLY #2750 [CDPHE RCRA; 29 m] | AA2: SAFEWAY INC. # 1587 [FRS; 21 m] | AB2: WORLD SAVINGS | AC2: 23 | AF2: SALLY BEAUTY SUPPLY #2750 | AG2: 29
